<?xml version="1.0" ?>
<!-- =================================================================================== -->
<!-- |    This document was autogenerated by xacro from dv.urdf.xacro                  | -->
<!-- |    EDITING THIS FILE BY HAND IS NOT RECOMMENDED                                 | -->
<!-- =================================================================================== -->
<robot name="dv" xmlns:controller="http://playerstage.sourceforge.net/gazebo/xmlschema/#controller" xmlns:interface="http://playerstage.sourceforge.net/gazebo/xmlschema/#interface" xmlns:sensor="http://playerstage.sourceforge.net/gazebo/xmlschema/#sensor" xmlns:xacro="http://playerstage.sourceforge.net/gazebo/xmlschema/#interface">
  <link name="base">
    <inertial>
      <origin rpy="0 0 0" xyz="0 0 0"/>
      <mass value="0"/>
      <inertia ixx="0" ixy="0" ixz="0" iyy="0" iyz="0" izz="0"/>
    </inertial>
  </link>
  <link name="torso">
    <visual>
      <origin rpy="0 0 0" xyz="0 0 0.2"/>
      <geometry>
        <box size="0.2 0.35 0.4"/>
      </geometry>
      <material name="lightgray">
        <color rgba=".4 .4 .4 0.4"/>
      </material>
      <origin rpy="0 0 0" xyz="0.2 0.2 0"/>
      <geometry>
        <box size="0.2 0.35 0.4"/>
      </geometry>
      <material name="lightgray">
        <color rgba=".4 .4 .4 0.4"/>
      </material>
    </visual>
    <collision>
      <origin rpy="0 0 0" xyz="-0.065 0 0.0"/>
      <geometry>
        <cylinder length="0.7" radius="0.27"/>
      </geometry>
    </collision>
    <inertial>
      <origin rpy="0 0 0" xyz="0.000000 0.000000 0.000000"/>
      <mass value="0.000000"/>
      <inertia ixx="0" ixy="0" ixz="0" iyy="0" iyz="0" izz="0"/>
    </inertial>
  </link>
  <link name="left_torso_itb">
    <visual>
      <origin rpy="0 0 0" xyz="0 0 0"/>
      <geometry>
        <box size=".059 0.118  0.032"/>
      </geometry>
      <material name="white">
        <color rgba="1 1 1 1"/>
      </material>
    </visual>
  </link>
  <link name="right_torso_itb">
    <visual>
      <origin rpy="0 0 0" xyz="0 0 0"/>
      <geometry>
        <box size=".059 0.118  0.032"/>
      </geometry>
      <material name="white">
        <color rgba="1 1 1 1"/>
      </material>
    </visual>
  </link>
  <link name="head">
    <visual>
      <origin rpy="0 0 0" xyz=".0 0 0"/>
      <geometry>
        <cylinder length="0.04" radius="0.09"/>
      </geometry>
      <material name="white">
        <color rgba="1 1 1 1"/>
      </material>
    </visual>
    <collision>
      <origin rpy="0 0 0" xyz="0.0 0 0.0"/>
      <geometry>
        <sphere radius="0.001"/>
      </geometry>
    </collision>
    <inertial>
      <origin rpy="0 0 0" xyz="0 0 0"/>
      <mass value="0"/>
      <inertia ixx="0" ixy="0" ixz="0" iyy="0" iyz="0" izz="0"/>
    </inertial>
  </link>
  <link name="sonar_ring">
    <visual>
      <origin rpy="0 0 0" xyz="0 0 0"/>
      <geometry>
        <cylinder length="0.01" radius="0.09"/>
      </geometry>
      <material name="white">
        <color rgba="1 1 1 1"/>
      </material>
    </visual>
    <collision>
      <origin rpy="0 0 0" xyz="0.0 0 0.0"/>
      <geometry>
        <sphere radius="0.001"/>
      </geometry>
    </collision>
    <inertial>
      <origin rpy="0 0 0" xyz="0 0 0"/>
      <mass value="0"/>
      <inertia ixx="0" ixy="0" ixz="0" iyy="0" iyz="0" izz="0"/>
    </inertial>
  </link>
  <link name="screen">
    <visual>
      <origin rpy="0 0 0" xyz=".005 .004 0"/>
      <geometry>
        <box size=".11 0.08  0.01"/>
      </geometry>
      <material name="darkblue">
        <color rgba=".1 .1 .1 1"/>
      </material>
    </visual>
    <collision>
      <origin rpy="0 0 0" xyz="0.0 0 0.0"/>
      <geometry>
        <sphere radius="0.001"/>
      </geometry>
    </collision>
    <inertial>
      <origin rpy="0 0 0" xyz="0 0 0"/>
      <mass value="0"/>
      <inertia ixx="0" ixy="0" ixz="0" iyy="0" iyz="0" izz="0"/>
    </inertial>
  </link>
  <link name="dummyhead1">
    <inertial>
      <origin rpy="0 0 0" xyz="0 0 0"/>
      <mass value="0"/>
      <inertia ixx="0" ixy="0" ixz="0" iyy="0" iyz="0" izz="0"/>
    </inertial>
  </link>
  <link name="collision_head_link_1">
    <visual>
      <origin rpy="0 0 0" xyz="0 0 0"/>
      <geometry>
        <sphere radius="0.001"/>
      </geometry>
      <material name="red">
        <color rgba="0.8 0.3 0.3 0.3"/>
      </material>
    </visual>
    <collision>
      <origin rpy="0 0 0.0" xyz="-0.05 -0.04 0.0"/>
      <geometry>
        <!-- <cylinder radius="0.18" length="0.4" /> -->
        <sphere radius="0.20"/>
      </geometry>
    </collision>
    <inertial>
      <origin rpy="0 0 0" xyz="0 0 0"/>
      <mass value="0"/>
      <inertia ixx="0" ixy="0" ixz="0" iyy="0" iyz="0" izz="0"/>
    </inertial>
  </link>
  <link name="collision_head_link_2">
    <visual>
      <origin rpy="0 0 0" xyz="0 0 0"/>
      <geometry>
        <sphere radius="0.001"/>
      </geometry>
      <material name="red">
        <color rgba="0.8 0.3 0.3 0.3"/>
      </material>
    </visual>
    <collision>
      <!-- <origin xyz="0.0 0.03 0.02" rpy="0 0 0" /> -->
      <origin rpy="0 0 0" xyz="-0.05 0.04 0.00"/>
      <geometry>
        <!-- <box size="0.34 0.27 0.14" /> -->
        <sphere radius="0.20"/>
      </geometry>
    </collision>
    <inertial>
      <origin rpy="0 0 0" xyz="0 0 0"/>
      <mass value="0"/>
      <inertia ixx="0" ixy="0" ixz="0" iyy="0" iyz="0" izz="0"/>
    </inertial>
  </link>
  <joint name="collision_head_1" type="fixed">
    <origin rpy="0 0 0" xyz="0.11 0 0.75"/>
    <parent link="base"/>
    <child link="collision_head_link_1"/>
  </joint>
  <joint name="collision_head_2" type="fixed">
    <origin rpy="0 0 0" xyz="0.11 0 0.75"/>
    <parent link="base"/>
    <child link="collision_head_link_2"/>
  </joint>
  <joint name="dummy" type="fixed">
    <origin rpy="0 0 0" xyz="0 0 0"/>
    <parent link="head"/>
    <child link="dummyhead1"/>
  </joint>
  <joint name="torso_t0" type="fixed">
    <origin rpy="0 0 0" xyz="0 0 0"/>
    <parent link="base"/>
    <child link="torso"/>
    <limit effort="50000" lower="-3.01" upper="3.01" velocity="10000"/>
  </joint>
  <joint name="left_torso_itb_fixed" type="fixed">
    <origin rpy="-1.571 3.1415 0" xyz="-0.08897 0.15593 0.389125"/>
    <parent link="torso"/>
    <child link="left_torso_itb"/>
  </joint>
  <joint name="right_torso_itb_fixed" type="fixed">
    <origin rpy="1.571 0 0" xyz="-0.08897 -0.15593 0.389125"/>
    <parent link="torso"/>
    <child link="right_torso_itb"/>
  </joint>
  <joint name="head_pan" type="revolute">
    <origin rpy="0 0 0" xyz="0.0947 0 0.686"/>
    <axis xyz="0 0 1"/>
    <parent link="torso"/>
    <child link="head"/>
    <limit effort="50000" lower="-1.571" upper="1.571" velocity="10000"/>
    <dynamics damping="0.0" friction="0.0"/>
  </joint>
  <joint name="head_nod" type="fixed">
    <origin rpy="1.9198622 0.0 1.571" xyz=".088 0.0 0.0"/>
    <parent link="head"/>
    <child link="screen"/>
  </joint>
  <joint name="sonar_s0" type="fixed">
    <origin rpy="0 0 0" xyz="0.0947 0 .817"/>
    <axis xyz="0 0 1"/>
    <parent link="torso"/>
    <child link="sonar_ring"/>
  </joint>
  <link name="right_upper_shoulder">
    <visual>
      <origin rpy="0 0 0" xyz="0 0 0.1361"/>
      <geometry>
        <cylinder length="0.2722" radius="0.06"/>
      </geometry>
      <material name="lightred">
        <color rgba=".8 .2 .2 1"/>
      </material>
    </visual>
    <collision>
      <origin rpy="0 0 0" xyz="0 0 0.1361"/>
      <geometry>
        <cylinder length="0.22" radius="0.15"/>
      </geometry>
    </collision>
    <inertial>
      <origin rpy="0 0 0" xyz="0.01463 0.00071 0.1747"/>
      <mass value="6.72194"/>
      <inertia ixx="57850125.31" ixy="-520359.79" ixz="8493325.12" iyy="52489408.45" iyz="148061.99" izz="35159370.95"/>
    </inertial>
  </link>
  <link name="right_lower_shoulder">
    <visual>
      <origin rpy="0 0 0" xyz="0 0 0"/>
      <geometry>
        <cylinder length="0.12" radius="0.06"/>
      </geometry>
      <material name="lightblue">
        <color rgba=".2 .2 .8 1"/>
      </material>
    </visual>
    <collision>
      <origin rpy="0 0 0" xyz="0 0 0"/>
      <geometry>
        <sphere radius="0.001"/>
      </geometry>
    </collision>
    <inertial>
      <!-- Excel spreadsheet rpy'd the wrong way -->
      <origin rpy="0 0 0" xyz="0.08084 0.00306 -0.00625"/>
      <mass value="2.473"/>
      <inertia ixx="10377586.32" ixy="-271135.65" ixz="-1880115.06" iyy="23516558.31" iyz="-113664.65" izz="17378647.03"/>
    </inertial>
  </link>
  <link name="right_upper_elbow">
    <visual>
      <origin rpy="0 0 0" xyz="0 0 -0.0535"/>
      <geometry>
        <cylinder length="0.107" radius="0.06"/>
      </geometry>
      <material name="lightblue">
        <color rgba=".2 .8 .2 1"/>
      </material>
    </visual>
    <collision>
      <origin rpy="0 0 0" xyz="0 0 0"/>
      <geometry>
        <cylinder length="0.05" radius="0.14"/>
      </geometry>
    </collision>
    <inertial>
      <origin rpy="0 0 0" xyz="0.0053 0.00033 0.1864"/>
      <mass value="4.64677"/>
      <inertia ixx="32431812.06" ixy="-463538.17" ixz="9365905.66" iyy="40985692.16" iyz="552388.07" izz="19524356.37"/>
    </inertial>
  </link>
  <link name="right_upper_elbow_visual">
    <visual>
      <origin rpy="0 0 0" xyz="0 0 0.1365"/>
      <geometry>
        <cylinder length="0.273" radius="0.06"/>
      </geometry>
      <material name="lightgreen">
        <color rgba=".2 .8 .2 1"/>
      </material>
    </visual>
    <collision>
      <origin rpy="0 0 0" xyz="0 0 0.1965"/>
      <geometry>
        <cylinder length="0.03" radius="0.12"/>
      </geometry>
    </collision>
  </link>
  <link name="right_lower_elbow">
    <visual>
      <origin rpy="0 0 0" xyz="0 0 0"/>
      <geometry>
        <cylinder length="0.10" radius="0.06"/>
      </geometry>
      <material name="lightblue">
        <color rgba=".2 .2 .8 1"/>
      </material>
    </visual>
    <collision>
      <origin rpy="0 0 0" xyz="-0.06 0.0 0.0"/>
      <geometry>
        <sphere radius="0.12"/>
      </geometry>
    </collision>
    <inertial>
      <!-- Excel spreadsheet rpy'd the wrong way -->
      <origin rpy="0 0 0" xyz="0.04756 0.00193 -0.01114"/>
      <mass value="1.5419"/>
      <inertia ixx="5107416.11" ixy="75334.36" ixz="-726352.15" iyy="9850465.59" iyz="-126769.7" izz="7477817.41"/>
    </inertial>
  </link>
  <link name="right_lower_elbow_highspeed_collision">
    <visual>
      <origin rpy="0 0 0" xyz="0 0 0"/>
      <geometry>
        <cylinder length="0.001" radius="0.001"/>
      </geometry>
      <material name="lightblue">
        <color rgba=".2 .2 .8 1"/>
      </material>
    </visual>
    <collision>
      <origin rpy="0 0 0" xyz="0.0 0.0 0.0"/>
      <geometry>
        <sphere radius="0.2"/>
      </geometry>
    </collision>
    <inertial>
      <origin rpy="0 0 0" xyz="0.0 0.0 0.0"/>
      <mass value="0.0"/>
      <inertia ixx="0" ixy="0" ixz="0" iyy="0" iyz="0" izz="0"/>
    </inertial>
  </link>
  <link name="right_upper_forearm">
    <visual>
      <origin rpy="0 0 0" xyz="0 0 -0.044"/>
      <geometry>
        <cylinder length="0.088" radius="0.06"/>
      </geometry>
      <material name="lightblue">
        <color rgba=".2 .8 .2 1"/>
      </material>
    </visual>
    <collision>
      <origin rpy="0 0 0" xyz="0 0 0"/>
      <geometry>
        <sphere radius="0.001"/>
      </geometry>
    </collision>
    <inertial>
      <origin rpy="0 0 0" xyz="0.00003 0.00781 0.15358"/>
      <mass value="2.38493"/>
      <inertia ixx="19119258.95" ixy="110238.58" ixz="251935.12" iyy="19066485.62" iyz="-857347.46" izz="4210603.57"/>
    </inertial>
  </link>
  <link name="right_upper_forearm_visual">
    <visual>
      <origin rpy="0 0 0" xyz="0 0 0.136"/>
      <geometry>
        <cylinder length="0.272" radius="0.06"/>
      </geometry>
      <material name="lightgreen">
        <color rgba=".2 .8 .2 1"/>
      </material>
    </visual>
    <collision>
      <origin rpy="0 0 0" xyz="0 0 0.10"/>
      <geometry>
        <cylinder length="0.12" radius="0.12"/>
      </geometry>
    </collision>
  </link>
  <link name="right_arm_itb">
    <visual>
      <origin rpy="0 0 0" xyz="0 0 0"/>
      <geometry>
        <box size=".059 0.118  0.032"/>
      </geometry>
      <material name="white">
        <color rgba="1 1 1 1"/>
      </material>
    </visual>
  </link>
  <link name="right_lower_forearm">
    <visual>
      <origin rpy="0 0 0" xyz="0 0 0"/>
      <geometry>
        <cylinder length="0.10" radius="0.06"/>
      </geometry>
      <material name="lightblue">
        <color rgba=".2 .2 .8 1"/>
      </material>
    </visual>
    <collision>
      <origin rpy="0 0 0" xyz="0 0 0"/>
      <geometry>
        <cylinder length="0.01" radius="0.12"/>
      </geometry>
    </collision>
    <inertial>
      <!-- Excel spreadsheet rpy'd the wrong way -->
      <origin rpy="0 0 0" xyz="0.05561 0.0056 0.00617"/>
      <mass value="1.84237"/>
      <inertia ixx="4933557.71" ixy="-451574.8" ixz="526859.69" iyy="8708729.69" iyz="79347.22" izz="6826642.12"/>
    </inertial>
  </link>
  <link name="right_lower_forearm_highspeed_collision">
    <visual>
      <origin rpy="0 0 0" xyz="0 0 0"/>
      <geometry>
        <cylinder length="0.001" radius="0.001"/>
      </geometry>
      <material name="lightblue">
        <color rgba=".2 .2 .8 1"/>
      </material>
    </visual>
    <collision>
      <origin rpy="0 0 0" xyz="0 0 0"/>
      <geometry>
        <cylinder length="0.01" radius="0.2"/>
      </geometry>
    </collision>
    <inertial>
      <origin rpy="0 0 0" xyz="0.0 0.0 0.0"/>
      <mass value="0.0"/>
      <inertia ixx="0" ixy="0" ixz="0" iyy="0" iyz="0" izz="0"/>
    </inertial>
  </link>
  <link name="right_wrist">
    <visual>
      <origin rpy="0 0 0" xyz="0 0 0"/>
      <geometry>
        <cylinder length="0.165" radius="0.06"/>
      </geometry>
      <material name="lightblue">
        <color rgba=".2 .8 .2 1"/>
      </material>
    </visual>
    <collision>
      <origin rpy="0 0 0" xyz="0 0 0"/>
      <geometry>
        <cylinder length="0.04" radius="0.12"/>
      </geometry>
    </collision>
    <inertial>
      <origin rpy="0 0 0" xyz="0.00287 -0.00096 0.02132"/>
      <mass value="0.39512"/>
      <inertia ixx="415154.02" ixy="36201.36" ixz="-1152.25" iyy="503156" iyz="-4119.4" izz="612144.38"/>
    </inertial>
  </link>
  <link name="right_wrist_highspeed_collision">
    <visual>
      <origin rpy="0 0 0" xyz="0 0 -0.0825"/>
      <geometry>
        <cylinder length="0.001" radius="0.001"/>
      </geometry>
      <material name="lightblue">
        <color rgba=".2 .8 .2 1"/>
      </material>
    </visual>
    <collision>
      <origin rpy="0 0 0" xyz="0 0 0"/>
      <geometry>
        <cylinder length="0.04" radius="0.2"/>
      </geometry>
    </collision>
    <inertial>
      <origin rpy="0 0 0" xyz="0.0 0.0 0.0"/>
      <mass value="0.0"/>
      <inertia ixx="0" ixy="0" ixz="0" iyy="0" iyz="0" izz="0"/>
    </inertial>
  </link>
  <link name="right_hand">
    <visual>
      <origin rpy="0 0 0" xyz="0 0 -0.0232"/>
      <geometry>
        <cylinder length="0.0464" radius="0.04"/>
      </geometry>
      <material name="lightred">
        <color rgba=".8 .2 .2 1"/>
      </material>
    </visual>
    <collision>
      <origin rpy="0 0 0" xyz="0 0 -0.0232 "/>
      <geometry>
        <cylinder length="0.04" radius="0.1"/>
      </geometry>
    </collision>
    <inertial>
      <origin rpy="0 0 0" xyz="0.01093 0.00042 -0.01532"/>
      <mass value="0.19125"/>
      <inertia ixx="175880" ixy="1470.73" ixz="24363.3" iyy="211663.77" iyz="1726.89" izz="237453.97"/>
    </inertial>
  </link>
  <link name="right_hand_camera">
    <visual>
      <origin rpy="0 0 0" xyz="0 0 0"/>
      <geometry>
        <cylinder length="0.01" radius="0.02"/>
      </geometry>
      <material name="blue">
        <color rgba="0 0 1 0.8"/>
      </material>
    </visual>
    <collision>
      <origin rpy="0 0 0" xyz="0 0 0"/>
      <geometry>
        <sphere radius="0.001"/>
      </geometry>
    </collision>
    <inertial>
      <origin rpy="0 0 0" xyz="0 0 0"/>
      <mass value="0"/>
      <inertia ixx="0" ixy="0" ixz="0" iyy="0" iyz="0" izz="0"/>
    </inertial>
  </link>
  <link name="right_hand_camera_axis">
    <visual>
      <origin rpy="0 0 0" xyz="0 0 0"/>
      <geometry>
        <cylinder length="0.01" radius="0.02"/>
      </geometry>
      <material name="blue">
        <color rgba="0 0 1 0.8"/>
      </material>
    </visual>
    <collision>
      <origin rpy="0 0 0" xyz="0 0 0"/>
      <geometry>
        <sphere radius="0.001"/>
      </geometry>
    </collision>
    <inertial>
      <origin rpy="0 0 0" xyz="0 0 0"/>
      <mass value="0"/>
      <inertia ixx="0" ixy="0" ixz="0" iyy="0" iyz="0" izz="0"/>
    </inertial>
  </link>
  <link name="right_hand_range">
    <visual>
      <origin rpy="0 0 0" xyz="0 0 0"/>
      <geometry>
        <box size="0.005 .02 .005"/>
      </geometry>
      <material name="blue">
        <color rgba="0 0 1 0.8"/>
      </material>
    </visual>
    <collision>
      <origin rpy="0 0 0" xyz="0 0 0"/>
      <geometry>
        <sphere radius="0.001"/>
      </geometry>
    </collision>
    <inertial>
      <origin rpy="0 0 0" xyz="0 0 0"/>
      <mass value="0"/>
      <inertia ixx="0" ixy="0" ixz="0" iyy="0" iyz="0" izz="0"/>
    </inertial>
  </link>
  <link name="right_gripper">
    <visual>
      <origin rpy="0 0 0" xyz="0 0 -0.02"/>
      <geometry>
        <box size="0.025 0.075 0.035"/>
      </geometry>
      <material name="lightred">
        <color rgba=".8 .2 .2 0.8"/>
      </material>
    </visual>
    <collision>
      <origin rpy="0 0 0" xyz="0 0 0"/>
      <geometry>
        <sphere radius="0.001"/>
      </geometry>
    </collision>
    <inertial>
      <origin rpy="0 0 0" xyz="0.000000 0.000000 0.000000"/>
      <mass value="0.0"/>
      <inertia ixx="0" ixy="0" ixz="0" iyy="0" iyz="0" izz="0"/>
    </inertial>
  </link>
  <joint name="right_s0" type="revolute">
    <origin rpy="0 0 -0.7854" xyz="0.065030 -0.259291 0.128570"/>
    <axis xyz="0 0 1"/>
    <parent link="torso"/>
    <child link="right_upper_shoulder"/>
    <limit effort="60.0" lower="-1.70167993878" upper="1.70167993878" velocity="2.5"/>
    <dynamics damping="0.0" friction="0.0"/>
  </joint>
  <joint name="right_s1" type="revolute">
    <origin rpy="-1.571 0 0" xyz="0.069 0 0.27035"/>
    <axis xyz="0 0 1"/>
    <parent link="right_upper_shoulder"/>
    <child link="right_lower_shoulder"/>
    <limit effort="60.0" lower="-2.147" upper="1.047" velocity="2.5"/>
    <dynamics damping="0.0" friction="0.0"/>
  </joint>
  <joint name="right_e0" type="revolute">
    <origin rpy="1.571 0 1.571" xyz="0.1019401 0 0"/>
    <axis xyz="0 0 1"/>
    <parent link="right_lower_shoulder"/>
    <child link="right_upper_elbow"/>
    <limit effort="60.0" lower="-3.05417993878" upper="3.05417993878" velocity="2.5"/>
    <dynamics damping="0.0" friction="0.0"/>
  </joint>
  <joint name="right_e0_fixed" type="fixed">
    <origin rpy="1.571 0 1.571" xyz="0.107 0 0"/>
    <axis xyz="0 0 1"/>
    <parent link="right_lower_shoulder"/>
    <child link="right_upper_elbow_visual"/>
  </joint>
  <joint name="right_e1" type="revolute">
    <origin rpy="-1.571 -1.571 0" xyz="0.069 0 0.26240989"/>
    <axis xyz="0 0 1"/>
    <parent link="right_upper_elbow"/>
    <child link="right_lower_elbow"/>
    <limit effort="60.0" lower="-0.05" upper="2.618" velocity="2.5"/>
    <dynamics damping="0.0" friction="0.0"/>
  </joint>
  <joint name="right_e1_fixed" type="fixed">
    <origin rpy="-1.571 -1.3819 0" xyz="0.069 0 0.25386"/>
    <axis xyz="0 0 1"/>
    <parent link="right_upper_elbow"/>
    <child link="right_lower_elbow_highspeed_collision"/>
  </joint>
  <joint name="right_w0" type="revolute">
    <origin rpy="1.571 0 1.571" xyz="0.09758772 0 0"/>
    <axis xyz="0 0 1"/>
    <parent link="right_lower_elbow"/>
    <child link="right_upper_forearm"/>
    <limit effort="20.0" lower="-3.059" upper="3.059" velocity="5.0"/>
    <dynamics damping="0.0" friction="0.0"/>
  </joint>
  <joint name="right_w0_fixed" type="fixed">
    <origin rpy="1.571 0 1.571" xyz="0.088 0 0"/>
    <axis xyz="0 0 1"/>
    <parent link="right_lower_elbow"/>
    <child link="right_upper_forearm_visual"/>
  </joint>
  <joint name="right_w0_to_itb_fixed" type="fixed">
    <origin rpy="-1.571 0 1.571" xyz="-0.0565 0 0.1301"/>
    <axis xyz="0 0 1"/>
    <parent link="right_upper_forearm"/>
    <child link="right_arm_itb"/>
  </joint>
  <joint name="right_w1" type="revolute">
    <origin rpy="-1.571 -1.571 0" xyz="0.01000042 0.000000275 0.2767"/>
    <axis xyz="0 0 1"/>
    <parent link="right_upper_forearm"/>
    <child link="right_lower_forearm"/>
    <limit effort="20.0" lower="-1.571" upper="2.094" velocity="5.0"/>
    <dynamics damping="0.0" friction="0.0"/>
  </joint>
  <joint name="right_w1_fixed" type="fixed">
    <origin rpy="-1.571 -1.571 0" xyz="0.01 0 0.27186"/>
    <axis xyz="0 0 1"/>
    <parent link="right_upper_forearm"/>
    <child link="right_lower_forearm_highspeed_collision"/>
  </joint>
  <joint name="right_w2" type="revolute">
    <origin rpy="1.571 0 1.571" xyz="0.115975 0 0"/>
    <axis xyz="0 0 1"/>
    <parent link="right_lower_forearm"/>
    <child link="right_wrist"/>
    <limit effort="20.0" lower="-3.059" upper="3.059" velocity="5.0"/>
    <dynamics damping="0.0" friction="0.0"/>
  </joint>
  <joint name="right_w2_fixed" type="fixed">
    <origin rpy="1.571 0 1.571" xyz="0.16555 0 0"/>
    <axis xyz="0 0 1"/>
    <parent link="right_lower_forearm"/>
    <child link="right_wrist_highspeed_collision"/>
  </joint>
  <joint name="right_hand" type="fixed">
    <origin rpy="0 0 0" xyz="0 0 0.11355"/>
    <axis xyz="0 0 1"/>
    <parent link="right_wrist"/>
    <child link="right_hand"/>
    <dynamics damping="0.0" friction="0.0"/>
  </joint>
  <joint name="right_hand_camera" type="fixed">
    <origin rpy="0 0 -1.57079633" xyz="0.03825 0.012 0.015355"/>
    <parent link="right_hand"/>
    <child link="right_hand_camera"/>
  </joint>
  <joint name="right_hand_camera_axis" type="fixed">
    <origin rpy="0 0 0" xyz="0.03825 0.012 0.015355"/>
    <parent link="right_hand"/>
    <child link="right_hand_camera_axis"/>
  </joint>
  <joint name="right_hand_range" type="fixed">
    <origin rpy="0 0 0" xyz="0.032 -0.020245 0.0288"/>
    <parent link="right_hand"/>
    <child link="right_hand_range"/>
  </joint>
  <joint name="right_endpoint" type="fixed">
    <origin rpy="0 0 0" xyz="0.0 0 0.05"/>
    <parent link="right_hand"/>
    <child link="right_gripper"/>
  </joint>
  <link name="left_upper_shoulder">
    <visual>
      <origin rpy="0 0 0" xyz="0 0 0.1361"/>
      <geometry>
        <cylinder length="0.2722" radius="0.06"/>
      </geometry>
      <material name="lightred">
        <color rgba=".8 .2 .2 1"/>
      </material>
    </visual>
    <collision>
      <origin rpy="0 0 0" xyz="0 0 0.1361"/>
      <geometry>
        <cylinder length="0.22" radius="0.15"/>
      </geometry>
    </collision>
    <inertial>
      <origin rpy="0 0 0" xyz="0.01463 0.00071 0.1747"/>
      <mass value="6.72194"/>
      <inertia ixx="57850125.31" ixy="-520359.79" ixz="8493325.12" iyy="52489408.45" iyz="148061.99" izz="35159370.95"/>
    </inertial>
  </link>
  <link name="left_lower_shoulder">
    <visual>
      <origin rpy="0 0 0" xyz="0 0 0"/>
      <geometry>
        <cylinder length="0.12" radius="0.06"/>
      </geometry>
      <material name="lightblue">
        <color rgba=".2 .2 .8 1"/>
      </material>
    </visual>
    <collision>
      <origin rpy="0 0 0" xyz="0 0 0"/>
      <geometry>
        <sphere radius="0.001"/>
      </geometry>
    </collision>
    <inertial>
      <!-- Excel spreadsheet rpy'd the wrong way -->
      <origin rpy="0 0 0" xyz="0.08084 0.00306 -0.00625"/>
      <mass value="2.473"/>
      <inertia ixx="10377586.32" ixy="-271135.65" ixz="-1880115.06" iyy="23516558.31" iyz="-113664.65" izz="17378647.03"/>
    </inertial>
  </link>
  <link name="left_upper_elbow">
    <visual>
      <origin rpy="0 0 0" xyz="0 0 -0.0535"/>
      <geometry>
        <cylinder length="0.107" radius="0.06"/>
      </geometry>
      <material name="lightblue">
        <color rgba=".2 .8 .2 1"/>
      </material>
    </visual>
    <collision>
      <origin rpy="0 0 0" xyz="0 0 0"/>
      <geometry>
        <cylinder length="0.05" radius="0.14"/>
      </geometry>
    </collision>
    <inertial>
      <origin rpy="0 0 0" xyz="0.0053 0.00033 0.1864"/>
      <mass value="4.64677"/>
      <inertia ixx="32431812.06" ixy="-463538.17" ixz="9365905.66" iyy="40985692.16" iyz="552388.07" izz="19524356.37"/>
    </inertial>
  </link>
  <link name="left_upper_elbow_visual">
    <visual>
      <origin rpy="0 0 0" xyz="0 0 0.1365"/>
      <geometry>
        <cylinder length="0.273" radius="0.06"/>
      </geometry>
      <material name="lightgreen">
        <color rgba=".2 .8 .2 1"/>
      </material>
    </visual>
    <collision>
      <origin rpy="0 0 0" xyz="0 0 0.1965"/>
      <geometry>
        <cylinder length="0.03" radius="0.12"/>
      </geometry>
    </collision>
  </link>
  <link name="left_lower_elbow">
    <visual>
      <origin rpy="0 0 0" xyz="0 0 0"/>
      <geometry>
        <cylinder length="0.10" radius="0.06"/>
      </geometry>
      <material name="lightblue">
        <color rgba=".2 .2 .8 1"/>
      </material>
    </visual>
    <collision>
      <origin rpy="0 0 0" xyz="-0.06 0.0 0.0"/>
      <geometry>
        <sphere radius="0.12"/>
      </geometry>
    </collision>
    <inertial>
      <!-- Excel spreadsheet rpy'd the wrong way -->
      <origin rpy="0 0 0" xyz="0.04756 0.00193 -0.01114"/>
      <mass value="1.5419"/>
      <inertia ixx="5107416.11" ixy="75334.36" ixz="-726352.15" iyy="9850465.59" iyz="-126769.7" izz="7477817.41"/>
    </inertial>
  </link>
  <link name="left_lower_elbow_highspeed_collision">
    <visual>
      <origin rpy="0 0 0" xyz="0 0 0"/>
      <geometry>
        <cylinder length="0.001" radius="0.001"/>
      </geometry>
      <material name="lightblue">
        <color rgba=".2 .2 .8 1"/>
      </material>
    </visual>
    <collision>
      <origin rpy="0 0 0" xyz="0.0 0.0 0.0"/>
      <geometry>
        <sphere radius="0.2"/>
      </geometry>
    </collision>
    <inertial>
      <origin rpy="0 0 0" xyz="0.0 0.0 0.0"/>
      <mass value="0.0"/>
      <inertia ixx="0" ixy="0" ixz="0" iyy="0" iyz="0" izz="0"/>
    </inertial>
  </link>
  <link name="left_upper_forearm">
    <visual>
      <origin rpy="0 0 0" xyz="0 0 -0.044"/>
      <geometry>
        <cylinder length="0.088" radius="0.06"/>
      </geometry>
      <material name="lightblue">
        <color rgba=".2 .8 .2 1"/>
      </material>
    </visual>
    <collision>
      <origin rpy="0 0 0" xyz="0 0 0"/>
      <geometry>
        <sphere radius="0.001"/>
      </geometry>
    </collision>
    <inertial>
      <origin rpy="0 0 0" xyz="0.00003 0.00781 0.15358"/>
      <mass value="2.38493"/>
      <inertia ixx="19119258.95" ixy="110238.58" ixz="251935.12" iyy="19066485.62" iyz="-857347.46" izz="4210603.57"/>
    </inertial>
  </link>
  <link name="left_upper_forearm_visual">
    <visual>
      <origin rpy="0 0 0" xyz="0 0 0.136"/>
      <geometry>
        <cylinder length="0.272" radius="0.06"/>
      </geometry>
      <material name="lightgreen">
        <color rgba=".2 .8 .2 1"/>
      </material>
    </visual>
    <collision>
      <origin rpy="0 0 0" xyz="0 0 0.10"/>
      <geometry>
        <cylinder length="0.12" radius="0.12"/>
      </geometry>
    </collision>
  </link>
  <link name="left_arm_itb">
    <visual>
      <origin rpy="0 0 0" xyz="0 0 0"/>
      <geometry>
        <box size=".059 0.118  0.032"/>
      </geometry>
      <material name="white">
        <color rgba="1 1 1 1"/>
      </material>
    </visual>
  </link>
  <link name="left_lower_forearm">
    <visual>
      <origin rpy="0 0 0" xyz="0 0 0"/>
      <geometry>
        <cylinder length="0.10" radius="0.06"/>
      </geometry>
      <material name="lightblue">
        <color rgba=".2 .2 .8 1"/>
      </material>
    </visual>
    <collision>
      <origin rpy="0 0 0" xyz="0 0 0"/>
      <geometry>
        <cylinder length="0.01" radius="0.12"/>
      </geometry>
    </collision>
    <inertial>
      <!-- Excel spreadsheet rpy'd the wrong way -->
      <origin rpy="0 0 0" xyz="0.05561 0.0056 0.00617"/>
      <mass value="1.84237"/>
      <inertia ixx="4933557.71" ixy="-451574.8" ixz="526859.69" iyy="8708729.69" iyz="79347.22" izz="6826642.12"/>
    </inertial>
  </link>
  <link name="left_lower_forearm_highspeed_collision">
    <visual>
      <origin rpy="0 0 0" xyz="0 0 0"/>
      <geometry>
        <cylinder length="0.001" radius="0.001"/>
      </geometry>
      <material name="lightblue">
        <color rgba=".2 .2 .8 1"/>
      </material>
    </visual>
    <collision>
      <origin rpy="0 0 0" xyz="0 0 0"/>
      <geometry>
        <cylinder length="0.01" radius="0.2"/>
      </geometry>
    </collision>
    <inertial>
      <origin rpy="0 0 0" xyz="0.0 0.0 0.0"/>
      <mass value="0.0"/>
      <inertia ixx="0" ixy="0" ixz="0" iyy="0" iyz="0" izz="0"/>
    </inertial>
  </link>
  <link name="left_wrist">
    <visual>
      <origin rpy="0 0 0" xyz="0 0 0"/>
      <geometry>
        <cylinder length="0.165" radius="0.06"/>
      </geometry>
      <material name="lightblue">
        <color rgba=".2 .8 .2 1"/>
      </material>
    </visual>
    <collision>
      <origin rpy="0 0 0" xyz="0 0 0"/>
      <geometry>
        <cylinder length="0.04" radius="0.12"/>
      </geometry>
    </collision>
    <inertial>
      <origin rpy="0 0 0" xyz="0.00287 -0.00096 0.02132"/>
      <mass value="0.39512"/>
      <inertia ixx="415154.02" ixy="36201.36" ixz="-1152.25" iyy="503156" iyz="-4119.4" izz="612144.38"/>
    </inertial>
  </link>
  <link name="left_wrist_highspeed_collision">
    <visual>
      <origin rpy="0 0 0" xyz="0 0 -0.0825"/>
      <geometry>
        <cylinder length="0.001" radius="0.001"/>
      </geometry>
      <material name="lightblue">
        <color rgba=".2 .8 .2 1"/>
      </material>
    </visual>
    <collision>
      <origin rpy="0 0 0" xyz="0 0 0"/>
      <geometry>
        <cylinder length="0.04" radius="0.2"/>
      </geometry>
    </collision>
    <inertial>
      <origin rpy="0 0 0" xyz="0.0 0.0 0.0"/>
      <mass value="0.0"/>
      <inertia ixx="0" ixy="0" ixz="0" iyy="0" iyz="0" izz="0"/>
    </inertial>
  </link>
  <link name="left_hand">
    <visual>
      <origin rpy="0 0 0" xyz="0 0 -0.0232"/>
      <geometry>
        <cylinder length="0.0464" radius="0.04"/>
      </geometry>
      <material name="lightred">
        <color rgba=".8 .2 .2 1"/>
      </material>
    </visual>
    <collision>
      <origin rpy="0 0 0" xyz="0 0 -0.0232 "/>
      <geometry>
        <cylinder length="0.04" radius="0.1"/>
      </geometry>
    </collision>
    <inertial>
      <origin rpy="0 0 0" xyz="0.01093 0.00042 -0.01532"/>
      <mass value="0.19125"/>
      <inertia ixx="175880" ixy="1470.73" ixz="24363.3" iyy="211663.77" iyz="1726.89" izz="237453.97"/>
    </inertial>
  </link>
  <link name="left_hand_camera">
    <visual>
      <origin rpy="0 0 0" xyz="0 0 0"/>
      <geometry>
        <cylinder length="0.01" radius="0.02"/>
      </geometry>
      <material name="blue">
        <color rgba="0 0 1 0.8"/>
      </material>
    </visual>
    <collision>
      <origin rpy="0 0 0" xyz="0 0 0"/>
      <geometry>
        <sphere radius="0.001"/>
      </geometry>
    </collision>
    <inertial>
      <origin rpy="0 0 0" xyz="0 0 0"/>
      <mass value="0"/>
      <inertia ixx="0" ixy="0" ixz="0" iyy="0" iyz="0" izz="0"/>
    </inertial>
  </link>
  <link name="left_hand_camera_axis">
    <visual>
      <origin rpy="0 0 0" xyz="0 0 0"/>
      <geometry>
        <cylinder length="0.01" radius="0.02"/>
      </geometry>
      <material name="blue">
        <color rgba="0 0 1 0.8"/>
      </material>
    </visual>
    <collision>
      <origin rpy="0 0 0" xyz="0 0 0"/>
      <geometry>
        <sphere radius="0.001"/>
      </geometry>
    </collision>
    <inertial>
      <origin rpy="0 0 0" xyz="0 0 0"/>
      <mass value="0"/>
      <inertia ixx="0" ixy="0" ixz="0" iyy="0" iyz="0" izz="0"/>
    </inertial>
  </link>
  <link name="left_hand_range">
    <visual>
      <origin rpy="0 0 0" xyz="0 0 0"/>
      <geometry>
        <box size="0.005 .02 .005"/>
      </geometry>
      <material name="blue">
        <color rgba="0 0 1 0.8"/>
      </material>
    </visual>
    <collision>
      <origin rpy="0 0 0" xyz="0 0 0"/>
      <geometry>
        <sphere radius="0.001"/>
      </geometry>
    </collision>
    <inertial>
      <origin rpy="0 0 0" xyz="0 0 0"/>
      <mass value="0"/>
      <inertia ixx="0" ixy="0" ixz="0" iyy="0" iyz="0" izz="0"/>
    </inertial>
  </link>
  <link name="left_gripper">
    <visual>
      <origin rpy="0 0 0" xyz="0 0 -0.02"/>
      <geometry>
        <box size="0.025 0.075 0.035"/>
      </geometry>
      <material name="lightred">
        <color rgba=".8 .2 .2 0.8"/>
      </material>
    </visual>
    <collision>
      <origin rpy="0 0 0" xyz="0 0 0"/>
      <geometry>
        <sphere radius="0.001"/>
      </geometry>
    </collision>
    <inertial>
      <origin rpy="0 0 0" xyz="0.000000 0.000000 0.000000"/>
      <mass value="0.0"/>
      <inertia ixx="0" ixy="0" ixz="0" iyy="0" iyz="0" izz="0"/>
    </inertial>
  </link>
  <joint name="left_s0" type="revolute">
    <origin rpy="0 0 0.7854" xyz="0.065030 0.259291 0.128570"/>
    <axis xyz="0 0 1"/>
    <parent link="torso"/>
    <child link="left_upper_shoulder"/>
    <limit effort="60.0" lower="-1.70167993878" upper="1.70167993878" velocity="2.5"/>
    <dynamics damping="0.0" friction="0.0"/>
  </joint>
  <joint name="left_s1" type="revolute">
    <origin rpy="-1.571 0 0" xyz="0.069 0 0.27035"/>
    <axis xyz="0 0 1"/>
    <parent link="left_upper_shoulder"/>
    <child link="left_lower_shoulder"/>
    <limit effort="60.0" lower="-2.147" upper="1.047" velocity="2.5"/>
    <dynamics damping="0.0" friction="0.0"/>
  </joint>
  <joint name="left_e0" type="revolute">
    <origin rpy="1.571 0 1.571" xyz="0.1019401 0 0"/>
    <axis xyz="0 0 1"/>
    <parent link="left_lower_shoulder"/>
    <child link="left_upper_elbow"/>
    <limit effort="60.0" lower="-3.05417993878" upper="3.05417993878" velocity="2.5"/>
    <dynamics damping="0.0" friction="0.0"/>
  </joint>
  <joint name="left_e0_fixed" type="fixed">
    <origin rpy="1.571 0 1.571" xyz="0.107 0 0"/>
    <axis xyz="0 0 1"/>
    <parent link="left_lower_shoulder"/>
    <child link="left_upper_elbow_visual"/>
  </joint>
  <joint name="left_e1" type="revolute">
    <origin rpy="-1.571 -1.571 0" xyz="0.069 0 0.26240989"/>
    <axis xyz="0 0 1"/>
    <parent link="left_upper_elbow"/>
    <child link="left_lower_elbow"/>
    <limit effort="60.0" lower="-0.05" upper="2.618" velocity="2.5"/>
    <dynamics damping="0.0" friction="0.0"/>
  </joint>
  <joint name="left_e1_fixed" type="fixed">
    <origin rpy="-1.571 -1.3819 0" xyz="0.069 0 0.25386"/>
    <axis xyz="0 0 1"/>
    <parent link="left_upper_elbow"/>
    <child link="left_lower_elbow_highspeed_collision"/>
  </joint>
  <joint name="left_w0" type="revolute">
    <origin rpy="1.571 0 1.571" xyz="0.09758772 0 0"/>
    <axis xyz="0 0 1"/>
    <parent link="left_lower_elbow"/>
    <child link="left_upper_forearm"/>
    <limit effort="20.0" lower="-3.059" upper="3.059" velocity="5.0"/>
    <dynamics damping="0.0" friction="0.0"/>
  </joint>
  <joint name="left_w0_fixed" type="fixed">
    <origin rpy="1.571 0 1.571" xyz="0.088 0 0"/>
    <axis xyz="0 0 1"/>
    <parent link="left_lower_elbow"/>
    <child link="left_upper_forearm_visual"/>
  </joint>
  <joint name="left_w0_to_itb_fixed" type="fixed">
    <origin rpy="-1.571 0 1.571" xyz="-0.0565 0 0.1301"/>
    <axis xyz="0 0 1"/>
    <parent link="left_upper_forearm"/>
    <child link="left_arm_itb"/>
  </joint>
  <joint name="left_w1" type="revolute">
    <origin rpy="-1.571 -1.571 0" xyz="0.01000042 0.000000275 0.2767"/>
    <axis xyz="0 0 1"/>
    <parent link="left_upper_forearm"/>
    <child link="left_lower_forearm"/>
    <limit effort="20.0" lower="-1.571" upper="2.094" velocity="5.0"/>
    <dynamics damping="0.0" friction="0.0"/>
  </joint>
  <joint name="left_w1_fixed" type="fixed">
    <origin rpy="-1.571 -1.571 0" xyz="0.01 0 0.27186"/>
    <axis xyz="0 0 1"/>
    <parent link="left_upper_forearm"/>
    <child link="left_lower_forearm_highspeed_collision"/>
  </joint>
  <joint name="left_w2" type="revolute">
    <origin rpy="1.571 0 1.571" xyz="0.115975 0 0"/>
    <axis xyz="0 0 1"/>
    <parent link="left_lower_forearm"/>
    <child link="left_wrist"/>
    <limit effort="20.0" lower="-3.059" upper="3.059" velocity="5.0"/>
    <dynamics damping="0.0" friction="0.0"/>
  </joint>
  <joint name="left_w2_fixed" type="fixed">
    <origin rpy="1.571 0 1.571" xyz="0.16555 0 0"/>
    <axis xyz="0 0 1"/>
    <parent link="left_lower_forearm"/>
    <child link="left_wrist_highspeed_collision"/>
  </joint>
  <joint name="left_hand" type="fixed">
    <origin rpy="0 0 0" xyz="0 0 0.11355"/>
    <axis xyz="0 0 1"/>
    <parent link="left_wrist"/>
    <child link="left_hand"/>
    <dynamics damping="0.0" friction="0.0"/>
  </joint>
  <joint name="left_hand_camera" type="fixed">
    <origin rpy="0 0 -1.57079633" xyz="0.03825 0.012 0.015355"/>
    <parent link="left_hand"/>
    <child link="left_hand_camera"/>
  </joint>
  <joint name="left_hand_camera_axis" type="fixed">
    <origin rpy="0 0 0" xyz="0.03825 0.012 0.015355"/>
    <parent link="left_hand"/>
    <child link="left_hand_camera_axis"/>
  </joint>
  <joint name="left_hand_range" type="fixed">
    <origin rpy="0 0 0" xyz="0.032 -0.020245 0.0288"/>
    <parent link="left_hand"/>
    <child link="left_hand_range"/>
  </joint>
  <joint name="left_endpoint" type="fixed">
    <origin rpy="0 0 0" xyz="0.0 0 0.05"/>
    <parent link="left_hand"/>
    <child link="left_gripper"/>
  </joint>
</robot>

